<?xml version="1.0"?>
<robot name="simple_car">

  <link name="base_footprint"></link>
  <joint name="base_link_joint" type="fixed">
    <parent link="base_footprint"/>
    <child link="base_link"/>
  </joint>

  <!-- Base link -->
  <link name="base_link">
    <visual>
      <origin rpy="0 0 0" xyz="0 0 0.2" /> <!-- displacement and orientation of the geometric centre of the link -->
      <geometry>
        <box size="0.5 0.25 0.15"/> <!-- length, width, height -->
      </geometry>
      <material name="blue">
        <color rgba="0.1 0.2 0.8 1.0"/>
      </material>
    </visual>
    <collision>
      <origin rpy="0 0 0" xyz="0 0 0.20625" />
      <geometry>
        <box size="0.5 0.25 0.15"/>
      </geometry>
    </collision>
    <inertial>
      <origin rpy="0 0 0" xyz="0 0 0.2" />
      <mass value="1.0"/> <!-- in kg -->
      <inertia ixx="0.05625" iyy="0.05625" izz="0.05625" ixy="0.0" ixz="0.0" iyz="0.0"/>
    </inertial>
  </link>

  <!-- Wheels -->
  <link name="right_wheel">
    <visual>
      <origin rpy="1.570795 0 0" xyz="0 0 0"/>
      <geometry><cylinder length="0.05" radius="0.1"/></geometry>
      <material name="black"><color rgba="0 0 0 1"/></material>
    </visual>
    <collision>
      <origin rpy="1.570795 0 0" xyz="0 0 0"/>
      <geometry><cylinder length="0.05" radius="0.1"/></geometry>
    </collision>
    <inertial>
      <origin rpy="1.570795 0 0" xyz="0 0 0"/>
      <mass value="0.2"/>
      <inertia ixx="0.0005625" iyy="0.0005625" izz="0.0005625" ixy="0.0" ixz="0.0" iyz="0.0"/>
    </inertial>
  </link>

  <link name="left_wheel">
    <visual>
      <origin rpy="1.570795 0 0" xyz="0 0 0"/>
      <geometry><cylinder length="0.05" radius="0.1"/></geometry>
      <material name="black"><color rgba="0 0 0 1"/></material>
    </visual>
    <collision>
      <origin rpy="1.570795 0 0" xyz="0 0 0"/>
      <geometry><cylinder length="0.05" radius="0.1"/></geometry>
    </collision>
    <inertial>
      <origin rpy="1.570795 0 0" xyz="0 0 0"/>
      <mass value="0.2"/>
      <inertia ixx="0.0005625" iyy="0.0005625" izz="0.0005625" ixy="0.0" ixz="0.0" iyz="0.0"/>
    </inertial>
  </link>

  <link name="caster">
    <visual>
      <origin rpy="0 0 0" xyz="0 0 0"/>
      <geometry><sphere radius="0.1"/></geometry>
      <material name="black"><color rgba="0 0 0 1"/></material>
    </visual>
    <collision>
      <origin rpy="0 0 0" xyz="0 0 0"/>
      <geometry><sphere radius="0.1"/></geometry>
    </collision>
    <inertial>
      <origin rpy="0 0 0" xyz="0 0 0"/>
      <mass value="0.2"/>
      <inertia ixx="0.0005625" iyy="0.0005625" izz="0.0005625" ixy="0.0" ixz="0.0" iyz="0.0"/>
    </inertial>
  </link>

  <link name="lidar">
    <visual>
      <origin rpy="0 0 0.05" xyz="0 0 0"/>
      <geometry><cylinder length="0.05" radius="0.05"/></geometry>
      <material name="black"><color rgba="0 0 0 1"/></material>
    </visual>
    <collision>
      <origin rpy="0 0 0.05" xyz="0 0 0"/>
      <geometry><cylinder length="0.05" radius="0.05"/></geometry>
    </collision>
    <inertial>
      <origin rpy="0 0 0" xyz="0 0 0"/>
      <mass value="1e-6"/>
      <inertia ixx="5.625e-07" iyy="5.625e-07" izz="5.625e-07" ixy="0.0" ixz="0.0" iyz="0.0"/>
    </inertial>
  </link>

  <link name="camera">
    <visual>
      <origin xyz="0 0 0" rpy="0 0 0"/>
      <geometry><box size="0.03 0.03 0.07"/></geometry>
      <material name="grey"><color rgba="0.3 0.3 0.3 1.0"/></material>
    </visual>
    <collision>
      <origin xyz="0 0 0" rpy="0 0 0"/>
      <geometry><box size="0.03 0.03 0.05"/></geometry>
    </collision>
    <inertial>
      <origin xyz="0 0 0" rpy="0 0 0"/>
      <mass value="1e-6"/>
      <inertia ixx="5.625e-07" iyy="5.625e-07" izz="5.625e-07" ixy="0.0" ixz="0.0" iyz="0.0"/>
    </inertial>
  </link>

  <link name="imu">
    <!-- <visual>
      <geometry>
        <box size="0.01 0.01 0.01"/>
      </geometry>
    </visual>
    <collision>
      <geometry><box size="0.01 0.01 0.01"/></geometry>
    </collision>
    <inertial>
      <origin xyz="0 0 0" rpy="0 0 0"/>
      <mass value="0.001"/>
      <inertia ixx="5.625e-07" iyy="5.625e-07" izz="5.625e-07" ixy="0.0" ixz="0.0" iyz="0.0"/>
    </inertial> -->
  </link>

  <!-- Joints -->
  <joint name="right_wheel_joint" type="continuous">
    <parent link="base_link"/>
    <child link="right_wheel"/>
    <origin xyz="-0.17 -0.15 0.1" rpy="0 0 0"/>
    <axis xyz="0 1 0"/>
    <limit effort="50000" velocity="10"/>
    <dynamics damping="1.0" friction="1.0"/>
  </joint>

  <joint name="left_wheel_joint" type="continuous">
    <parent link="base_link"/>
    <child link="left_wheel"/>
    <origin xyz="-0.17 0.15 0.1" rpy="0 0 0"/>
    <axis xyz="0 1 0"/>
    <limit effort="50000" velocity="10"/> <!-- effort is torque -->
    <dynamics damping="1.0" friction="1.0"/>
  </joint>

  <joint name="caster_joint" type="fixed">
    <parent link="base_link"/>
    <child link="caster"/>
    <origin xyz="0.17 0 0.1" rpy="0 0 0"/>
  </joint>

  <joint name="lidar_joint" type="fixed">
    <parent link="base_link"/>
    <child link="lidar"/>
    <origin xyz="0 0 0.28" rpy="0 0 0"/>
    <axis xyz="0 1 0" rpy="0 0 0"/>
  </joint>

  <joint name="camera_joint" type="fixed">
    <parent link="base_link"/>
    <child link="camera"/>
    <origin xyz="0.25 0 0.225" rpy="0 0 0"/>
  </joint>

  <joint name='imu_joint' type='fixed'>
    <parent link="base_link"/>
    <child link="imu"/>
    <origin xyz="0 0 0.01" rpy="0 0 0"/>
  </joint>

  <!-- Gazebo setups -->
  <gazebo reference="base_link">
    <mu1>0.2</mu1>
    <mu2>0.2</mu2>
  </gazebo>
  <gazebo reference="left_wheel">
    <mu1>0.2</mu1>
    <mu2>0.2</mu2>
  </gazebo>
  <gazebo reference="right_wheel">
    <mu1>0.2</mu1>
    <mu2>0.2</mu2>
  </gazebo>
  <gazebo reference="caster">
    <mu1>0.000002</mu1>
    <mu2>0.000002</mu2>
  </gazebo>

  <gazebo>
    <plugin filename="gz-sim-diff-drive-system" name="gz::sim::systems::DiffDrive">
      <left_joint>left_wheel_joint</left_joint>
      <right_joint>right_wheel_joint</right_joint>
      <wheel_separation>0.3</wheel_separation>
      <wheel_diameter>0.2</wheel_diameter>
      <max_linear_acceleration>10</max_linear_acceleration>
      
      <topic>cmd_vel</topic>
      <tf_topic>/tf</tf_topic>
      <odom_topic>odom</odom_topic>
      <frame_id>odom</frame_id>
      <child_frame_id>base_footprint</child_frame_id>
      <update_rate>20</update_rate>
    </plugin>

    <plugin name="gz::sim::systems::JointStatePublisher" filename="gz-sim-joint-state-publisher-system">
      <topic>joint_states</topic>
      <joint_name>left_wheel_joint</joint_name>
      <joint_name>right_wheel_joint</joint_name>
    </plugin>

    <plugin name="gz::sim::systems::Sensors" filename="gz-sim-sensors-system">
      <render_engine>ogre2</render_engine>
    </plugin>

    <plugin filename="gz-sim-imu-system" name="gz::sim::systems::Imu"></plugin>
    
    <plugin
      filename="gz-sim-pose-publisher-system" name="gz::sim::systems::PosePublisher">
      <!-- <pose_name_prefix>base_footprint</pose_name_prefix> -->
      <use_pose_vector_msg>true</use_pose_vector_msg>
      <publish_nested_model_pose>true</publish_nested_model_pose>
    </plugin>
  </gazebo>

  <gazebo reference='lidar'>
    <sensor name="gpu_lidar" type="gpu_lidar">
      <pose relative_to='lidar'>0 0 0 0 0 0</pose>
      <!-- <topic>scan</topic> -->
      <topic>lidar</topic>
      <gz_frame_id>lidar</gz_frame_id>
      <update_rate>20</update_rate>
      <lidar>
        <scan>
          <horizontal>
            <samples>720</samples>
            <resolution>1</resolution>
            <min_angle>-3.14</min_angle>
            <max_angle>3.14</max_angle>
          </horizontal>
          <vertical>
            <samples>16</samples>
            <resolution>1</resolution>
            <min_angle>-0.2</min_angle>   <!-- about -11 deg -->
            <max_angle>0.2</max_angle>    <!-- about +11 deg -->
          </vertical>
        </scan>
        <range>
          <min>0.01</min>
          <max>20</max>
          <resolution>0.005</resolution>
        </range>
        <noise>
          <type>gaussian</type>
          <mean>0.0</mean>
          <stddev>0.001</stddev>
        </noise>
      </lidar>
      <always_on>1</always_on>
      <visualize>1</visualize>
    </sensor>
  </gazebo>

  <gazebo reference='camera'>
    <sensor name="camera" type="camera">
      <pose relative_to='camera'>0 0 0 0 0 0</pose>
      <topic>camera/image</topic>
      <update_rate>5</update_rate>
      <camera>
        <horizontal_fov>1.5708</horizontal_fov>
        <image>
          <width>640</width>
          <height>480</height>
          <format>R8G8B8</format>
        </image>
        <clip>
          <near>0.1</near>
          <far>15</far>
        </clip>
        <noise>
          <type>gaussian</type>
          <mean>0.0</mean>
          <stddev>0.007</stddev>
        </noise>
        <camera_info_topic>camera/camera_info</camera_info_topic>
      </camera>
      <always_on>1</always_on>
      <visualize>1</visualize>
    </sensor>
  </gazebo>

  <gazebo reference='imu'>
    <sensor name="imu" type="imu">
      <pose relative_to='imu'>0 0 0 0 0 0</pose>
      <topic>imu</topic>
      <update_rate>30</update_rate>
      <gz_frame_id>imu</gz_frame_id>
      <always_on>1</always_on>
      <visualize>1</visualize>
      <imu>
        <angular_velocity>
          <noise>
            <type>gaussian</type>
            <mean>0.0</mean>
            <stddev>2e-4</stddev>
            <bias_mean>0.0000075</bias_mean>
            <bias_stddev>0.0000008</bias_stddev>
          </noise>
        </angular_velocity>
        <linear_acceleration>
          <noise>
            <type>gaussian</type>
            <mean>0.0</mean>
            <stddev>1.7e-2</stddev>
            <bias_mean>0.1</bias_mean>
            <bias_stddev>0.001</bias_stddev>
          </noise>
        </linear_acceleration>
      </imu>
    </sensor>
  </gazebo>

  <!-- <gazebo reference='camera'>
    <sensor name="depth_camera" type="rgbd_camera">
      <pose relative_to='camera'>0 0 0 0 0 0</pose>
      <always_on>true</always_on>
      <visualize>true</visualize>
      <update_rate>5</update_rate>
      <topic>depth_camera</topic>
      <gz_frame_id>camera</gz_frame_id>
      <camera>
        <horizontal_fov>1.5708</horizontal_fov>
        <image>
          <width>640</width>
          <height>480</height>
        </image>
        <clip>
          <near>0.1</near>
          <far>10</far>
        </clip>
      </camera>
      <baseline>0.2</baseline>
      <pointCloudCutoff>0.5</pointCloudCutoff>
      <pointCloudCutoffMax>3.0</pointCloudCutoffMax>
      <distortionK1>0</distortionK1>
      <distortionK2>0</distortionK2>
      <distortionK3>0</distortionK3>
      <distortionT1>0</distortionT1>
      <distortionT2>0</distortionT2>
      <CxPrime>0</CxPrime>
      <Cx>0</Cx>
      <Cy>0</Cy>
      <focalLength>0</focalLength>
      <hackBaseline>0</hackBaseline>
    </sensor>
  </gazebo> -->

</robot>

